<robot
  name="ra605">
  <link
    name="floor">
    <inertial>
      <origin
        xyz="0.0032233 4.3488E-16 -0.005"
        rpy="0 0 0" />
      <mass
        value="39.999" />
      <inertia
        ixx="13.334"
        ixy="2.7365E-15"
        ixz="-2.1807E-19"
        iyy="13.334"
        iyz="-4.6565E-14"
        izz="26.667" />
    </inertial>
    <visual>
      <origin
        xyz="0 0 0"
        rpy="0 0 0" />
      <geometry>
        <mesh
          filename="package://ra605/meshes/floor.STL" />
      </geometry>
      <material
        name="">
        <color
          rgba="0.79216 0.81961 0.93333 1" />
      </material>
    </visual>
    <collision>
      <origin
        xyz="0 0 0"
        rpy="0 0 0" />
      <geometry>
        <mesh
          filename="package://ra605/meshes/floor.STL" />
      </geometry>
    </collision>
  </link>
  <link
    name="Link1">
    <inertial>
      <origin
        xyz="0.02083 0.0026698 0.11878"
        rpy="0 0 0" />
      <mass
        value="50.478" />
      <inertia
        ixx="16.554"
        ixy="-0.0007393"
        ixz="-0.5302"
        iyy="16.7"
        iyz="-0.054433"
        izz="26.907" />
    </inertial>
    <visual>
      <origin
        xyz="0 0 0"
        rpy="0 0 0" />
      <geometry>
        <mesh
          filename="package://ra605/meshes/Link1.STL" />
      </geometry>
      <material
        name="">
        <color
          rgba="0.79216 0.81961 0.93333 1" />
      </material>
    </visual>
    <collision>
      <origin
        xyz="0 0 0"
        rpy="0 0 0" />
      <geometry>
        <mesh
          filename="package://ra605/meshes/Link1.STL" />
      </geometry>
    </collision>
  </link>
  <joint
    name="joint1"
    type="fixed">
    <origin
      xyz="0 0 0"
      rpy="0 0 0" />
    <parent
      link="floor" />
    <child
      link="Link1" />
    <axis
      xyz="0 0 0" />
  </joint>
  <link
    name="Link2">
    <inertial>
      <origin
        xyz="0.02083 0.0026698 0.10822"
        rpy="0 0 0" />
      <mass
        value="50.478" />
      <inertia
        ixx="16.554"
        ixy="-0.0007393"
        ixz="-0.5302"
        iyy="16.7"
        iyz="-0.054433"
        izz="26.907" />
    </inertial>
    <visual>
      <origin
        xyz="0 0 0"
        rpy="0 0 0" />
      <geometry>
        <mesh
          filename="package://ra605/meshes/Link2.STL" />
      </geometry>
      <material
        name="">
        <color
          rgba="0.79216 0.81961 0.93333 1" />
      </material>
    </visual>
    <collision>
      <origin
        xyz="0 0 0"
        rpy="0 0 0" />
      <geometry>
        <mesh
          filename="package://ra605/meshes/Link2.STL" />
      </geometry>
    </collision>
  </link>
  <joint
    name="joint2"
    type="continuous">
    <origin
      xyz="0 0 0.227"
      rpy="0 0 0" />
    <parent
      link="Link1" />
    <child
      link="Link2" />
    <axis
      xyz="0 0 1" />
  </joint>
  <link
    name="Link3">
    <inertial>
      <origin
        xyz="-0.0098112 0.018062 0.15034"
        rpy="0 0 0" />
      <mass
        value="7.4696" />
      <inertia
        ixx="0.1459"
        ixy="-0.00043183"
        ixz="0.00057326"
        iyy="0.11313"
        iyz="0.00031929"
        izz="0.049061" />
    </inertial>
    <visual>
      <origin
        xyz="0 0 0"
        rpy="0 0 0" />
      <geometry>
        <mesh
          filename="package://ra605/meshes/Link3.STL" />
      </geometry>
      <material
        name="">
        <color
          rgba="0.79216 0.81961 0.93333 1" />
      </material>
    </visual>
    <collision>
      <origin
        xyz="0 0 0"
        rpy="0 0 0" />
      <geometry>
        <mesh
          filename="package://ra605/meshes/Link3.STL" />
      </geometry>
    </collision>
  </link>
  <joint
    name="joint3"
    type="continuous">
    <origin
      xyz="0.033223 0 0.148"
      rpy="0 0 0" />
    <parent
      link="Link2" />
    <child
      link="Link3" />
    <axis
      xyz="0 1 0" />
  </joint>
  <link
    name="Link4">
    <inertial>
      <origin
        xyz="0.012393 0.0026698 0.59622"
        rpy="0 0 0" />
      <mass
        value="50.478" />
      <inertia
        ixx="16.554"
        ixy="-0.0007393"
        ixz="-0.5302"
        iyy="16.7"
        iyz="-0.054433"
        izz="26.907" />
    </inertial>
    <visual>
      <origin
        xyz="0 0 0"
        rpy="0 0 0" />
      <geometry>
        <mesh
          filename="package://ra605/meshes/Link4.STL" />
      </geometry>
      <material
        name="">
        <color
          rgba="0.79216 0.81961 0.93333 1" />
      </material>
    </visual>
    <collision>
      <origin
        xyz="0 0 0"
        rpy="0 0 0" />
      <geometry>
        <mesh
          filename="package://ra605/meshes/Link4.STL" />
      </geometry>
    </collision>
  </link>
  <joint
    name="joint4"
    type="continuous">
    <origin
      xyz="0 0 0.34"
      rpy="0 0 0" />
    <parent
      link="Link3" />
    <child
      link="Link4" />
    <axis
      xyz="0 1 0" />
  </joint>
  <link
    name="Link5">
    <inertial>
      <origin
        xyz="0.11355 -4.9558E-05 6.7458E-05"
        rpy="0 0 0" />
      <mass
        value="2.9699" />
      <inertia
        ixx="0.0070689"
        ixy="7.7383E-06"
        ixz="-1.1277E-06"
        iyy="0.017626"
        iyz="4.1381E-06"
        izz="0.019679" />
    </inertial>
    <visual>
      <origin
        xyz="0 0 0"
        rpy="0 0 0" />
      <geometry>
        <mesh
          filename="package://ra605/meshes/Link5.STL" />
      </geometry>
      <material
        name="">
        <color
          rgba="0.79216 0.81961 0.93333 1" />
      </material>
    </visual>
    <collision>
      <origin
        xyz="0 0 0"
        rpy="0 0 0" />
      <geometry>
        <mesh
          filename="package://ra605/meshes/Link5.STL" />
      </geometry>
    </collision>
  </link>
  <joint
    name="joint5"
    type="continuous">
    <origin
      xyz="0.099 0 0.04"
      rpy="0 0 0" />
    <parent
      link="Link4" />
    <child
      link="Link5" />
    <axis
      xyz="1 0 0" />
  </joint>
  <link
    name="Link6">
    <inertial>
      <origin
        xyz="0.03645 0.00025111 0.016042"
        rpy="0 0 0" />
      <mass
        value="2.6849E-06" />
      <inertia
        ixx="1.8401E-10"
        ixy="-2.1851E-25"
        ixz="-2.2778E-27"
        iyy="2.0089E-12"
        iyz="2.1784E-14"
        izz="1.8201E-10" />
    </inertial>
    <visual>
      <origin
        xyz="0 0 0"
        rpy="0 0 0" />
      <geometry>
        <mesh
          filename="package://ra605/meshes/Link6.STL" />
      </geometry>
      <material
        name="">
        <color
          rgba="0.79216 0.81961 0.93333 1" />
      </material>
    </visual>
    <collision>
      <origin
        xyz="0 0 0"
        rpy="0 0 0" />
      <geometry>
        <mesh
          filename="package://ra605/meshes/Link6.STL" />
      </geometry>
    </collision>
  </link>
  <joint
    name="joint6"
    type="continuous">
    <origin
      xyz="0.239 0 0"
      rpy="0 0 0" />
    <parent
      link="Link5" />
    <child
      link="Link6" />
    <axis
      xyz="0 1 0" />
  </joint>
  <link
    name="Link7">
    <inertial>
      <origin
        xyz="-0.006961 -2.7357E-07 5.6015E-05"
        rpy="0 0 0" />
      <mass
        value="0.039323" />
      <inertia
        ixx="2.1351E-05"
        ixy="4.2173E-11"
        ixz="7.3242E-09"
        iyy="1.1532E-05"
        iyz="2.2491E-10"
        izz="1.1567E-05" />
    </inertial>
    <visual>
      <origin
        xyz="0 0 0"
        rpy="0 0 0" />
      <geometry>
        <mesh
          filename="package://ra605/meshes/Link7.STL" />
      </geometry>
      <material
        name="">
        <color
          rgba="0.79216 0.81961 0.93333 1" />
      </material>
    </visual>
    <collision>
      <origin
        xyz="0 0 0"
        rpy="0 0 0" />
      <geometry>
        <mesh
          filename="package://ra605/meshes/Link7.STL" />
      </geometry>
    </collision>
  </link>
  <joint
    name="joint7"
    type="continuous">
    <origin
      xyz="0.0865 0 0"
      rpy="0 0 0" />
    <parent
      link="Link6" />
    <child
      link="Link7" />
    <axis
      xyz="1 0 0" />
  </joint>
</robot>