<robot
  name="ra605">
  <link
    name="floor1">
    <inertial>
      <origin
        xyz="-0.027867 3.7215E-06 -0.1165"
        rpy="0 0 0" />
      <mass
        value="39.999" />
      <inertia
        ixx="13.334"
        ixy="1.7928E-15"
        ixz="-6.8678E-18"
        iyy="13.334"
        iyz="-4.6579E-14"
        izz="26.667" />
    </inertial>
    <visual>
      <origin
        xyz="0 0 0"
        rpy="0 0 0" />
      <geometry>
        <mesh
          filename="package://ra605/meshes/floor1.STL" />
      </geometry>
      <material
        name="">
        <color
          rgba="0.79216 0.81961 0.93333 1" />
      </material>
    </visual>
    <collision>
      <origin
        xyz="0 0 0"
        rpy="0 0 0" />
      <geometry>
        <mesh
          filename="package://ra605/meshes/floor1.STL" />
      </geometry>
    </collision>
  </link>
  <link
    name="Link2">
    <inertial>
      <origin
        xyz="0.037351 0.0019611 1.382E-05"
        rpy="0 0 0" />
      <mass
        value="21.943" />
      <inertia
        ixx="0.14975"
        ixy="0.0016032"
        ixz="-3.0665E-05"
        iyy="0.13013"
        iyz="1.5416E-05"
        izz="0.16732" />
    </inertial>
    <visual>
      <origin
        xyz="0 0 0"
        rpy="0 0 0" />
      <geometry>
        <mesh
          filename="package://ra605/meshes/Link2.STL" />
      </geometry>
      <material
        name="">
        <color
          rgba="1 1 1 1" />
      </material>
    </visual>
    <collision>
      <origin
        xyz="0 0 0"
        rpy="0 0 0" />
      <geometry>
        <mesh
          filename="package://ra605/meshes/Link2.STL" />
      </geometry>
    </collision>
  </link>
  <joint
    name="joint1"
    type="fixed">
    <origin
      xyz="0 0 0"
      rpy="0 -1.2246E-16 3.1416" />
    <parent
      link="floor1" />
    <child
      link="Link2" />
    <axis
      xyz="0 0 0" />
  </joint>
  <link
    name="Link3">
    <inertial>
      <origin
        xyz="0.012541 -0.0034973 0.082141"
        rpy="0 0 0" />
      <mass
        value="7.6212" />
      <inertia
        ixx="0.035843"
        ixy="0.00046535"
        ixz="-0.0053569"
        iyy="0.038538"
        iyz="0.0016388"
        izz="0.02369" />
    </inertial>
    <visual>
      <origin
        xyz="0 0 0"
        rpy="0 0 0" />
      <geometry>
        <mesh
          filename="package://ra605/meshes/Link3.STL" />
      </geometry>
      <material
        name="">
        <color
          rgba="1 1 1 1" />
      </material>
    </visual>
    <collision>
      <origin
        xyz="0 0 0"
        rpy="0 0 0" />
      <geometry>
        <mesh
          filename="package://ra605/meshes/Link3.STL" />
      </geometry>
    </collision>
  </link>
  <joint
    name="joint2"
    type="continuous">
    <origin
      xyz="0.027867 0.1185 0"
      rpy="1.5708 -1.2246E-16 -3.1416" />
    <parent
      link="Link2" />
    <child
      link="Link3" />
    <axis
      xyz="0 0 1" />
  </joint>
  <link
    name="Link4">
    <inertial>
      <origin
        xyz="-0.0098344 0.017961 0.15004"
        rpy="0 0 0" />
      <mass
        value="20.11" />
      <inertia
        ixx="0.39179"
        ixy="-0.0011467"
        ixz="0.0015973"
        iyy="0.30339"
        iyz="0.0013522"
        izz="0.13207" />
    </inertial>
    <visual>
      <origin
        xyz="0 0 0"
        rpy="0 0 0" />
      <geometry>
        <mesh
          filename="package://ra605/meshes/Link4.STL" />
      </geometry>
      <material
        name="">
        <color
          rgba="1 1 1 1" />
      </material>
    </visual>
    <collision>
      <origin
        xyz="0 0 0"
        rpy="0 0 0" />
      <geometry>
        <mesh
          filename="package://ra605/meshes/Link4.STL" />
      </geometry>
    </collision>
  </link>
  <joint
    name="joint4"
    type="continuous">
    <origin
      xyz="0.03 0 0.145"
      rpy="0 0 0" />
    <parent
      link="Link3" />
    <child
      link="Link4" />
    <axis
      xyz="0 1 0" />
  </joint>
  <link
    name="Link5">
    <inertial>
      <origin
        xyz="0.00081491 -0.0023378 0.019022"
        rpy="0 0 0" />
      <mass
        value="6.7196" />
      <inertia
        ixx="0.015647"
        ixy="-1.3353E-05"
        ixz="-0.0031024"
        iyy="0.028001"
        iyz="-0.00028452"
        izz="0.024631" />
    </inertial>
    <visual>
      <origin
        xyz="0 0 0"
        rpy="0 0 0" />
      <geometry>
        <mesh
          filename="package://ra605/meshes/Link5.STL" />
      </geometry>
      <material
        name="">
        <color
          rgba="1 1 1 1" />
      </material>
    </visual>
    <collision>
      <origin
        xyz="0 0 0"
        rpy="0 0 0" />
      <geometry>
        <mesh
          filename="package://ra605/meshes/Link5.STL" />
      </geometry>
    </collision>
  </link>
  <joint
    name="joint5"
    type="continuous">
    <origin
      xyz="0 0 0.34"
      rpy="0 0 0" />
    <parent
      link="Link4" />
    <child
      link="Link5" />
    <axis
      xyz="0 1 0" />
  </joint>
  <link
    name="Link6">
    <inertial>
      <origin
        xyz="0.11367 -5.0401E-05 -6.5671E-05"
        rpy="0 0 0" />
      <mass
        value="3.0032" />
      <inertia
        ixx="0.0072168"
        ixy="2.3984E-06"
        ixz="-1.6373E-06"
        iyy="0.01773"
        iyz="4.1659E-06"
        izz="0.019919" />
    </inertial>
    <visual>
      <origin
        xyz="0 0 0"
        rpy="0 0 0" />
      <geometry>
        <mesh
          filename="package://ra605/meshes/Link6.STL" />
      </geometry>
      <material
        name="">
        <color
          rgba="0.79216 0.81961 0.93333 1" />
      </material>
    </visual>
    <collision>
      <origin
        xyz="0 0 0"
        rpy="0 0 0" />
      <geometry>
        <mesh
          filename="package://ra605/meshes/Link6.STL" />
      </geometry>
    </collision>
  </link>
  <joint
    name="joint6"
    type="continuous">
    <origin
      xyz="0.0989999999999995 0 0.0400000000000098"
      rpy="0 0 0" />
    <parent
      link="Link5" />
    <child
      link="Link6" />
    <axis
      xyz="1 0 0" />
  </joint>
  <link
    name="Link7">
    <inertial>
      <origin
        xyz="0.018322 0.0036986 -5.462E-06"
        rpy="0 0 0" />
      <mass
        value="1.025" />
      <inertia
        ixx="0.00064842"
        ixy="6.948E-05"
        ixz="1.729E-07"
        iyy="0.0012602"
        iyz="-1.4446E-07"
        izz="0.0011735" />
    </inertial>
    <visual>
      <origin
        xyz="0 0 0"
        rpy="0 0 0" />
      <geometry>
        <mesh
          filename="package://ra605/meshes/Link7.STL" />
      </geometry>
      <material
        name="">
        <color
          rgba="1 1 1 1" />
      </material>
    </visual>
    <collision>
      <origin
        xyz="0 0 0"
        rpy="0 0 0" />
      <geometry>
        <mesh
          filename="package://ra605/meshes/Link7.STL" />
      </geometry>
    </collision>
  </link>
  <joint
    name="joint7"
    type="continuous">
    <origin
      xyz="0.239 0 0"
      rpy="0 0 0" />
    <parent
      link="Link6" />
    <child
      link="Link7" />
    <axis
      xyz="0 1 0" />
  </joint>
  <link
    name="Link8">
    <inertial>
      <origin
        xyz="0.011822 3.6422E-06 -5.5243E-05"
        rpy="0 0 0" />
      <mass
        value="0.10765" />
      <inertia
        ixx="5.7757E-05"
        ixy="9.6255E-12"
        ixz="1.9881E-08"
        iyy="3.1197E-05"
        iyz="4.7029E-13"
        izz="3.1292E-05" />
    </inertial>
    <visual>
      <origin
        xyz="0 0 0"
        rpy="0 0 0" />
      <geometry>
        <mesh
          filename="package://ra605/meshes/Link8.STL" />
      </geometry>
      <material
        name="">
        <color
          rgba="0.99608 0.99608 1 1" />
      </material>
    </visual>
    <collision>
      <origin
        xyz="0 0 0"
        rpy="0 0 0" />
      <geometry>
        <mesh
          filename="package://ra605/meshes/Link8.STL" />
      </geometry>
    </collision>
  </link>
  <joint
    name="joint8"
    type="continuous">
    <origin
      xyz="0.0677 0 0"
      rpy="0 0 0" />
    <parent
      link="Link7" />
    <child
      link="Link8" />
    <axis
      xyz="1 0 0" />
  </joint>
</robot>