<robot
  name="RA605_710.SLDASM">
  <link
    name="base_link">
    <inertial>
      <origin
        xyz="-0.0032233 -0.005 4.3569E-16"
        rpy="0 0 0" />
      <mass
        value="39.999" />
      <inertia
        ixx="13.334"
        ixy="2.1807E-19"
        ixz="-2.7365E-15"
        iyy="26.667"
        iyz="-4.5749E-14"
        izz="13.334" />
    </inertial>
    <visual>
      <origin
        xyz="0 0 0"
        rpy="0 0 0" />
      <geometry>
        <mesh
          filename="package://RA605_710.SLDASM/meshes/base_link.STL" />
      </geometry>
      <material
        name="">
        <color
          rgba="0.79216 0.81961 0.93333 1" />
      </material>
    </visual>
    <collision>
      <origin
        xyz="0 0 0"
        rpy="0 0 0" />
      <geometry>
        <mesh
          filename="package://RA605_710.SLDASM/meshes/base_link.STL" />
      </geometry>
    </collision>
  </link>
  <link
    name="Link1">
    <inertial>
      <origin
        xyz="-0.0032233 -0.005 3.797E-16"
        rpy="0 0 0" />
      <mass
        value="39.999" />
      <inertia
        ixx="13.334"
        ixy="9.0784E-18"
        ixz="-1.8504E-15"
        iyy="26.667"
        iyz="-4.5736E-14"
        izz="13.334" />
    </inertial>
    <visual>
      <origin
        xyz="0 0 0"
        rpy="0 0 0" />
      <geometry>
        <mesh
          filename="package://RA605_710.SLDASM/meshes/Link1.STL" />
      </geometry>
      <material
        name="">
        <color
          rgba="0.79216 0.81961 0.93333 1" />
      </material>
    </visual>
    <collision>
      <origin
        xyz="0 0 0"
        rpy="0 0 0" />
      <geometry>
        <mesh
          filename="package://RA605_710.SLDASM/meshes/Link1.STL" />
      </geometry>
    </collision>
  </link>
  <joint
    name="j1"
    type="fixed">
    <origin
      xyz="0 0 0"
      rpy="0 0 0" />
    <parent
      link="base_link" />
    <child
      link="Link1" />
    <axis
      xyz="0 0 0" />
  </joint>
  <link
    name="Link2">
    <inertial>
      <origin
        xyz="0.0032233 3.7961E-16 -0.232"
        rpy="0 0 0" />
      <mass
        value="39.999" />
      <inertia
        ixx="13.334"
        ixy="1.8504E-15"
        ixz="-9.0784E-18"
        iyy="13.334"
        iyz="-4.6552E-14"
        izz="26.667" />
    </inertial>
    <visual>
      <origin
        xyz="0 0 0"
        rpy="0 0 0" />
      <geometry>
        <mesh
          filename="package://RA605_710.SLDASM/meshes/Link2.STL" />
      </geometry>
      <material
        name="">
        <color
          rgba="0.79216 0.81961 0.93333 1" />
      </material>
    </visual>
    <collision>
      <origin
        xyz="0 0 0"
        rpy="0 0 0" />
      <geometry>
        <mesh
          filename="package://RA605_710.SLDASM/meshes/Link2.STL" />
      </geometry>
    </collision>
  </link>
  <joint
    name="j2"
    type="revolute">
    <origin
      xyz="0 0.227 0"
      rpy="1.5708 -1.2246E-16 -3.1416" />
    <parent
      link="Link1" />
    <child
      link="Link2" />
    <axis
      xyz="0 0 1" />
    <limit
      lower="-3.1"
      upper="3.1"
      effort="0"
      velocity="0" />
  </joint>
</robot>