<robot
  name="RA605_710">
  <link
    name="base_link">
    <inertial>
      <origin
        xyz="-0.00322329614662994 -0.005 4.32638133916442E-16"
        rpy="0 0 0" />
      <mass
        value="39.9992146018366" />
      <inertia
        ixx="13.3336666552129"
        ixy="2.18068724778341E-19"
        ixz="-2.73645750664298E-15"
        iyy="26.6666666568492"
        iyz="-4.57489937427496E-14"
        izz="13.3336666552129" />
    </inertial>
    <visual>
      <origin
        xyz="0 0 0"
        rpy="0 0 0" />
      <geometry>
        <mesh
          filename="package://RA605_710/meshes/base_link.STL" />
      </geometry>
      <material
        name="">
        <color
          rgba="0.792156862745098 0.819607843137255 0.933333333333333 1" />
      </material>
    </visual>
    <collision>
      <origin
        xyz="0 0 0"
        rpy="0 0 0" />
      <geometry>
        <mesh
          filename="package://RA605_710/meshes/base_link.STL" />
      </geometry>
    </collision>
  </link>
  <link
    name="Link1">
    <inertial>
      <origin
        xyz="-0.0032233 -0.005 3.797E-16"
        rpy="0 0 0" />
      <mass
        value="39.999" />
      <inertia
        ixx="13.334"
        ixy="9.0784E-18"
        ixz="-1.8504E-15"
        iyy="26.667"
        iyz="-4.5736E-14"
        izz="13.334" />
    </inertial>
    <visual>
      <origin
        xyz="0 0 0"
        rpy="0 0 0" />
      <geometry>
        <mesh
          filename="package://RA605_710/meshes/Link1.STL" />
      </geometry>
      <material
        name="">
        <color
          rgba="0.79216 0.81961 0.93333 1" />
      </material>
    </visual>
    <collision>
      <origin
        xyz="0 0 0"
        rpy="0 0 0" />
      <geometry>
        <mesh
          filename="package://RA605_710/meshes/Link1.STL" />
      </geometry>
    </collision>
  </link>
  <joint
    name="j1"
    type="fixed">
    <origin
      xyz="0 0 0"
      rpy="0 0 0" />
    <parent
      link="base_link" />
    <child
      link="Link1" />
    <axis
      xyz="0 0 0" />
  </joint>
  <link
    name="Link2">
    <inertial>
      <origin
        xyz="0.0032233 3.7961E-16 -0.232"
        rpy="0 0 0" />
      <mass
        value="39.999" />
      <inertia
        ixx="13.334"
        ixy="1.8504E-15"
        ixz="-9.0784E-18"
        iyy="13.334"
        iyz="-4.6552E-14"
        izz="26.667" />
    </inertial>
    <visual>
      <origin
        xyz="0 0 0"
        rpy="0 0 0" />
      <geometry>
        <mesh
          filename="package://RA605_710/meshes/Link2.STL" />
      </geometry>
      <material
        name="">
        <color
          rgba="0.79216 0.81961 0.93333 1" />
      </material>
    </visual>
    <collision>
      <origin
        xyz="0 0 0"
        rpy="0 0 0" />
      <geometry>
        <mesh
          filename="package://RA605_710/meshes/Link2.STL" />
      </geometry>
    </collision>
  </link>
  <joint
    name="j2"
    type="continuous">
    <origin
      xyz="0 0.227 0"
      rpy="1.5707963267949 -1.22460635382238E-16 -3.14159265358979" />
    <parent
      link="Link1" />
    <child
      link="Link2" />
    <axis
      xyz="0 0 1" />
  </joint>
</robot>