<robot
  name="RA605_710_GB">
  <link
    name="base_link">
    <inertial>
      <origin
        xyz="0.00322329614662995 4.35236639886933E-16 -0.005"
        rpy="0 0 0" />
      <mass
        value="39.9992146018366" />
      <inertia
        ixx="13.3336666552129"
        ixy="2.73645750664298E-15"
        ixz="-2.18068724783876E-19"
        iyy="13.3336666552129"
        iyz="-4.65653775686255E-14"
        izz="26.6666666568492" />
    </inertial>
    <visual>
      <origin
        xyz="0 0 0"
        rpy="0 0 0" />
      <geometry>
        <mesh
          filename="package://RA605_710_GB/meshes/base_link.STL" />
      </geometry>
      <material
        name="">
        <color
          rgba="0.792156862745098 0.819607843137255 0.933333333333333 1" />
      </material>
    </visual>
    <collision>
      <origin
        xyz="0 0 0"
        rpy="0 0 0" />
      <geometry>
        <mesh
          filename="package://RA605_710_GB/meshes/base_link.STL" />
      </geometry>
    </collision>
  </link>
  <link
    name="base_Link">
    <inertial>
      <origin
        xyz="-0.0197115625412548 0.118584097089081 0.00272663309408005"
        rpy="0 0 0" />
      <mass
        value="50.6963005253788" />
      <inertia
        ixx="16.5548968121191"
        ixy="0.532783129588136"
        ixz="-0.00034057520373012"
        iyy="26.9234564467821"
        iyz="-0.0543017260136554"
        izz="16.7157961544257" />
    </inertial>
    <visual>
      <origin
        xyz="0 0 0"
        rpy="0 0 0" />
      <geometry>
        <mesh
          filename="package://RA605_710_GB/meshes/base_Link.STL" />
      </geometry>
      <material
        name="">
        <color
          rgba="0.792156862745098 0.819607843137255 0.933333333333333 1" />
      </material>
    </visual>
    <collision>
      <origin
        xyz="0 0 0"
        rpy="0 0 0" />
      <geometry>
        <mesh
          filename="package://RA605_710_GB/meshes/base_Link.STL" />
      </geometry>
    </collision>
  </link>
  <joint
    name="base_fix"
    type="fixed">
    <origin
      xyz="0 0 0"
      rpy="1.5707963267949 0 3.14159265358979" />
    <parent
      link="base_link" />
    <child
      link="base_Link" />
    <axis
      xyz="0 0 0" />
  </joint>
  <link
    name="wire">
    <inertial>
      <origin
        xyz="-0.0725051844188676 0.0266556692847321 0.0973200776244476"
        rpy="0 0 0" />
      <mass
        value="0.21821313758791" />
      <inertia
        ixx="0.000930045437457021"
        ixy="7.05554574080555E-08"
        ixz="-0.0003344023473386"
        iyy="0.00124404162085488"
        iyz="1.27872690899019E-07"
        izz="0.000372837191484093" />
    </inertial>
    <visual>
      <origin
        xyz="0 0 0"
        rpy="0 0 0" />
      <geometry>
        <mesh
          filename="package://RA605_710_GB/meshes/wire.STL" />
      </geometry>
      <material
        name="">
        <color
          rgba="0.792156862745098 0.819607843137255 0.933333333333333 1" />
      </material>
    </visual>
    <collision>
      <origin
        xyz="0 0 0"
        rpy="0 0 0" />
      <geometry>
        <mesh
          filename="package://RA605_710_GB/meshes/wire.STL" />
      </geometry>
    </collision>
  </link>
  <joint
    name="wire"
    type="fixed">
    <origin
      xyz="0.14178 0.09965 0.088375"
      rpy="0 -1.5708 0" />
    <parent
      link="base_Link" />
    <child
      link="wire" />
    <axis
      xyz="0 0 0" />
  </joint>
  <link
    name="Link2">
    <inertial>
      <origin
        xyz="0.019712 0.0027266 -0.10842"
        rpy="0 0 0" />
      <mass
        value="50.696" />
      <inertia
        ixx="16.555"
        ixy="0.00034058"
        ixz="-0.53278"
        iyy="16.716"
        iyz="-0.054302"
        izz="26.923" />
    </inertial>
    <visual>
      <origin
        xyz="0 0 0"
        rpy="0 0 0" />
      <geometry>
        <mesh
          filename="package://RA605_710_GB/meshes/Link2.STL" />
      </geometry>
      <material
        name="">
        <color
          rgba="0.79216 0.81961 0.93333 1" />
      </material>
    </visual>
    <collision>
      <origin
        xyz="0 0 0"
        rpy="0 0 0" />
      <geometry>
        <mesh
          filename="package://RA605_710_GB/meshes/Link2.STL" />
      </geometry>
    </collision>
  </link>
  <joint
    name="joint2"
    type="continuous">
    <origin
      xyz="0 0.227 0"
      rpy="1.5707963267949 -1.22460635382238E-16 -3.14159265358979" />
    <parent
      link="base_Link" />
    <child
      link="Link2" />
    <axis
      xyz="0 0 1" />
  </joint>
  <link
    name="Link3">
    <inertial>
      <origin
        xyz="-0.0098112 0.018062 0.15034"
        rpy="0 0 0" />
      <mass
        value="7.4696" />
      <inertia
        ixx="0.1459"
        ixy="-0.00043183"
        ixz="0.00057326"
        iyy="0.11313"
        iyz="0.00031929"
        izz="0.049061" />
    </inertial>
    <visual>
      <origin
        xyz="0 0 0"
        rpy="0 0 0" />
      <geometry>
        <mesh
          filename="package://RA605_710_GB/meshes/Link3.STL" />
      </geometry>
      <material
        name="">
        <color
          rgba="0.79216 0.81961 0.93333 1" />
      </material>
    </visual>
    <collision>
      <origin
        xyz="0 0 0"
        rpy="0 0 0" />
      <geometry>
        <mesh
          filename="package://RA605_710_GB/meshes/Link3.STL" />
      </geometry>
    </collision>
  </link>
  <joint
    name="joint3"
    type="continuous">
    <origin
      xyz="0.033223 0 0.148"
      rpy="0 0 0" />
    <parent
      link="Link2" />
    <child
      link="Link3" />
    <axis
      xyz="0 1 0" />
  </joint>
  <link
    name="Link4">
    <inertial>
      <origin
        xyz="-0.013512 0.0027266 -0.59642"
        rpy="0 0 0" />
      <mass
        value="50.696" />
      <inertia
        ixx="16.555"
        ixy="0.00034058"
        ixz="-0.53278"
        iyy="16.716"
        iyz="-0.054302"
        izz="26.923" />
    </inertial>
    <visual>
      <origin
        xyz="0 0 0"
        rpy="0 0 0" />
      <geometry>
        <mesh
          filename="package://RA605_710_GB/meshes/Link4.STL" />
      </geometry>
      <material
        name="">
        <color
          rgba="0.79216 0.81961 0.93333 1" />
      </material>
    </visual>
    <collision>
      <origin
        xyz="0 0 0"
        rpy="0 0 0" />
      <geometry>
        <mesh
          filename="package://RA605_710_GB/meshes/Link4.STL" />
      </geometry>
    </collision>
  </link>
  <joint
    name="joint4"
    type="continuous">
    <origin
      xyz="0 0 0.34"
      rpy="0 0 0" />
    <parent
      link="Link3" />
    <child
      link="Link4" />
    <axis
      xyz="0 1 0" />
  </joint>
  <link
    name="Link5">
    <inertial>
      <origin
        xyz="0.11355 -4.9558E-05 -6.7458E-05"
        rpy="0 0 0" />
      <mass
        value="2.9699" />
      <inertia
        ixx="0.0070689"
        ixy="7.7383E-06"
        ixz="-1.1277E-06"
        iyy="0.017626"
        iyz="4.1381E-06"
        izz="0.019679" />
    </inertial>
    <visual>
      <origin
        xyz="0 0 0"
        rpy="0 0 0" />
      <geometry>
        <mesh
          filename="package://RA605_710_GB/meshes/Link5.STL" />
      </geometry>
      <material
        name="">
        <color
          rgba="0.79216 0.81961 0.93333 1" />
      </material>
    </visual>
    <collision>
      <origin
        xyz="0 0 0"
        rpy="0 0 0" />
      <geometry>
        <mesh
          filename="package://RA605_710_GB/meshes/Link5.STL" />
      </geometry>
    </collision>
  </link>
  <joint
    name="joint5"
    type="continuous">
    <origin
      xyz="0.09900000000002 0 0.0399999999979752"
      rpy="0 0 0" />
    <parent
      link="Link4" />
    <child
      link="Link5" />
    <axis
      xyz="1 0 0" />
  </joint>
  <link
    name="Link6">
    <inertial>
      <origin
        xyz="0.03645 0.00025111 -0.016042"
        rpy="0 0 0" />
      <mass
        value="1" />
      <inertia
        ixx="1.8401E-10"
        ixy="7.8323E-26"
        ixz="-4.0836E-27"
        iyy="2.0089E-12"
        iyz="2.1784E-14"
        izz="1.8201E-10" />
    </inertial>
    <visual>
      <origin
        xyz="0 0 0"
        rpy="0 0 0" />
      <geometry>
        <mesh
          filename="package://RA605_710_GB/meshes/Link6.STL" />
      </geometry>
      <material
        name="">
        <color
          rgba="0.79216 0.81961 0.93333 1" />
      </material>
    </visual>
    <collision>
      <origin
        xyz="0 0 0"
        rpy="0 0 0" />
      <geometry>
        <mesh
          filename="package://RA605_710_GB/meshes/Link6.STL" />
      </geometry>
    </collision>
  </link>
  <joint
    name="joint6"
    type="continuous">
    <origin
      xyz="0.239000000000001 0 0"
      rpy="0 0 0" />
    <parent
      link="Link5" />
    <child
      link="Link6" />
    <axis
      xyz="1 0 0" />
  </joint>
  <link
    name="Link7">
    <inertial>
      <origin
        xyz="-0.006961 7.9999E-08 -5.6016E-05"
        rpy="0 0 0" />
      <mass
        value="0.039323" />
      <inertia
        ixx="2.1351E-05"
        ixy="-4.0583E-12"
        ixz="7.3243E-09"
        iyy="1.1532E-05"
        iyz="2.0856E-12"
        izz="1.1567E-05" />
    </inertial>
    <visual>
      <origin
        xyz="0 0 0"
        rpy="0 0 0" />
      <geometry>
        <mesh
          filename="package://RA605_710_GB/meshes/Link7.STL" />
      </geometry>
      <material
        name="">
        <color
          rgba="0.79216 0.81961 0.93333 1" />
      </material>
    </visual>
    <collision>
      <origin
        xyz="0 0 0"
        rpy="0 0 0" />
      <geometry>
        <mesh
          filename="package://RA605_710_GB/meshes/Link7.STL" />
      </geometry>
    </collision>
  </link>
  <joint
    name="joint7"
    type="continuous">
    <origin
      xyz="0.0864999999999757 0 0"
      rpy="0 0 0" />
    <parent
      link="Link6" />
    <child
      link="Link7" />
    <axis
      xyz="1 0 0" />
  </joint>
</robot>